{"name": "test_error_handling_in_archive", "status": "passed", "description": "Test error handling in archive_old_context.", "attachments": [{"name": "stdout", "source": "14b6e45a-a55e-41b7-868e-2652e89f210e-attachment.txt", "type": "text/plain"}], "start": 1753819436290, "stop": 1753819436291, "uuid": "5f126348-c909-4f29-86bc-5946d59ff776", "historyId": "ef305e2fa1a71d24d4ee4da17e1437b5", "testCaseId": "ef305e2fa1a71d24d4ee4da17e1437b5", "fullName": "tests.unit.core.test_supabase_context_coverage.TestSupabaseContextIntegration#test_error_handling_in_archive", "labels": [{"name": "parentSuite", "value": "tests.unit.core"}, {"name": "suite", "value": "test_supabase_context_coverage"}, {"name": "subSuite", "value": "TestSupabaseContextIntegration"}, {"name": "host", "value": "Yannick-Mac-Gillavry-werk.local"}, {"name": "thread", "value": "90219-MainThread"}, {"name": "framework", "value": "pytest"}, {"name": "language", "value": "cpython3"}, {"name": "package", "value": "tests.unit.core.test_supabase_context_coverage"}], "titlePath": ["tests", "unit", "core", "test_supabase_context_coverage.py", "TestSupabaseContextIntegration"]}