{"name": "test_error_handling_in_save", "status": "passed", "description": "Test error handling in save_context.", "start": 1753819436287, "stop": 1753819436287, "uuid": "4b1c518c-6e3a-4043-82e2-8f000ca2b2bd", "historyId": "7f242e494536bc6e59032573a1c15baf", "testCaseId": "7f242e494536bc6e59032573a1c15baf", "fullName": "tests.unit.core.test_supabase_context_coverage.TestSupabaseContextIntegration#test_error_handling_in_save", "labels": [{"name": "parentSuite", "value": "tests.unit.core"}, {"name": "suite", "value": "test_supabase_context_coverage"}, {"name": "subSuite", "value": "TestSupabaseContextIntegration"}, {"name": "host", "value": "Yannick-Mac-Gillavry-werk.local"}, {"name": "thread", "value": "90219-MainThread"}, {"name": "framework", "value": "pytest"}, {"name": "language", "value": "cpython3"}, {"name": "package", "value": "tests.unit.core.test_supabase_context_coverage"}], "titlePath": ["tests", "unit", "core", "test_supabase_context_coverage.py", "TestSupabaseContextIntegration"]}