{"name": "test_exception_handling", "status": "passed", "description": "Test exception handling in confidence calculation.", "start": 1753819429045, "stop": 1753819429045, "uuid": "af708e93-4519-4b4b-90b5-4dd0ba143468", "historyId": "68405085d47281d4e821c9a7ac28adfe", "testCaseId": "68405085d47281d4e821c9a7ac28adfe", "fullName": "tests.unit.core.test_llm_client_coverage.TestConfidenceFromLogprobs#test_exception_handling", "labels": [{"name": "parentSuite", "value": "tests.unit.core"}, {"name": "suite", "value": "test_llm_client_coverage"}, {"name": "subSuite", "value": "TestConfidenceFromLogprobs"}, {"name": "host", "value": "Yannick-Mac-Gillavry-werk.local"}, {"name": "thread", "value": "90219-MainThread"}, {"name": "framework", "value": "pytest"}, {"name": "language", "value": "cpython3"}, {"name": "package", "value": "tests.unit.core.test_llm_client_coverage"}], "titlePath": ["tests", "unit", "core", "test_llm_client_coverage.py", "TestConfidenceFromLogprobs"]}