{"name": "test_error_handling_in_get", "status": "passed", "description": "Test error handling in get_context.", "start": 1753819436289, "stop": 1753819436289, "uuid": "bde2aeca-77cd-488d-a31e-774300d532e9", "historyId": "d851e6ff650735fe26968c0bb9781fa4", "testCaseId": "d851e6ff650735fe26968c0bb9781fa4", "fullName": "tests.unit.core.test_supabase_context_coverage.TestSupabaseContextIntegration#test_error_handling_in_get", "labels": [{"name": "parentSuite", "value": "tests.unit.core"}, {"name": "suite", "value": "test_supabase_context_coverage"}, {"name": "subSuite", "value": "TestSupabaseContextIntegration"}, {"name": "host", "value": "Yannick-Mac-Gillavry-werk.local"}, {"name": "thread", "value": "90219-MainThread"}, {"name": "framework", "value": "pytest"}, {"name": "language", "value": "cpython3"}, {"name": "package", "value": "tests.unit.core.test_supabase_context_coverage"}], "titlePath": ["tests", "unit", "core", "test_supabase_context_coverage.py", "TestSupabaseContextIntegration"]}